<?xml version="1.0" ?>
<!-- =================================================================================== -->
<!-- |    This document was autogenerated by xacro from standalone_arm.urdf.xacro      | -->
<!-- |    EDITING THIS FILE BY HAND IS NOT RECOMMENDED                                 | -->
<!-- =================================================================================== -->
<robot name="jaco" xmlns:body="http://playerstage.sourceforge.net/gazebo/xmlschema/#body" xmlns:controller="http://playerstage.sourceforge.net/gazebo/xmlschema/#controller" xmlns:gazebo="http://playerstage.sourceforge.net/gazebo/xmlschema/#gz" xmlns:geom="http://playerstage.sourceforge.net/gazebo/xmlschema/#geom" xmlns:interface="http://playerstage.sourceforge.net/gazebo/xmlschema/#interface" xmlns:joint="http://playerstage.sourceforge.net/gazebo/xmlschema/#joint" xmlns:model="http://playerstage.sourceforge.net/gazebo/xmlschema/#model" xmlns:physics="http://playerstage.sourceforge.net/gazebo/xmlschema/#physics" xmlns:renderable="http://playerstage.sourceforge.net/gazebo/xmlschema/#renderable" xmlns:rendering="http://playerstage.sourceforge.net/gazebo/xmlschema/#rendering" xmlns:sensor="http://playerstage.sourceforge.net/gazebo/xmlschema/#sensor" xmlns:xacro="http://ros.org/wiki/xacro" xmlns:xi="http://www.w3.org/2001/XInclude">
  <!--
  Author: Kelsey Hawkins 
  Contributers: Jimmy Da Silva, Ajit Krisshna N L, Muhammad Asif Rana 
-->
  <!-- Inertia parameters -->
  <link name="root">
    <visual>
      <origin rpy="0 0 0" xyz="0 0 0"/>
      <geometry>
        <box size="0 0 0"/>
      </geometry>
    </visual>
    <collision>
      <origin rpy="0 0 0" xyz="0 0 0"/>
      <geometry>
        <box size="0 0 0"/>
      </geometry>
    </collision>
  </link>
  <joint name="jaco_base_joint" type="fixed">
    <parent link="root"/>
    <child link="jaco_base_link"/>
    <origin rpy="0 0 0" xyz="0 0 0"/>
  </joint>
  <link name="jaco_base_link">
    <visual>
      <geometry>
        <mesh filename="package://jaco2_description/meshes/jaco/visual/base.dae"/>
      </geometry>
    </visual>
    <collision>
      <geometry>
        <mesh filename="package://jaco2_description/meshes/jaco/collision/base.stl"/>
      </geometry>
    </collision>
    <inertial>
      <mass value="0.752103"/>
      <origin xyz="0 0 0"/>
      <inertia ixx="0.009025" ixy="-0.000002" ixz="-0.000005" iyx="-0.000002" iyy="0.009007" iyz="0.000000" izx="-0.000005" izy="0.000000" izz="0.000704"/>
    </inertial>
  </link>
  <joint name="jaco_shoulder_pan_joint" type="continuous">
    <parent link="jaco_base_link"/>
    <child link="jaco_shoulder_link"/>
    <origin rpy="0 0 -1.570796325" xyz="0.0 0.0 0.15675"/>
    <axis xyz="0 0 -1"/>
    <limit effort="18.0" velocity="0.75"/>
    <dynamics damping="0.0" friction="0.0"/>
  </joint>
  <link name="jaco_shoulder_link">
    <visual>
      <geometry>
        <mesh filename="package://jaco2_description/meshes/jaco/visual/shoulder.dae"/>
      </geometry>
    </visual>
    <collision>
      <geometry>
        <mesh filename="package://jaco2_description/meshes/jaco/collision/shoulder.stl"/>
      </geometry>
    </collision>
    <inertial>
      <mass value="0.839784"/>
      <origin xyz="0 0 0"/>
      <inertia ixx="0.005735" ixy="0.000000" ixz="0.000000" iyx="0.000000" iyy="0.005801" iyz="0.000496" izx="0.000000" izy="0.000496" izz="0.000570"/>
    </inertial>
  </link>
  <joint name="jaco_shoulder_lift_joint" type="revolute">
    <parent link="jaco_shoulder_link"/>
    <child link="jaco_upper_arm_link"/>
    <origin rpy="0 1.570796325 0" xyz="0.0 0.0 0.11875"/>
    <axis xyz="0 0 1"/>
    <limit effort="30.5" lower="0.872665" upper="5.41052" velocity="1.0"/>
    <dynamics damping="0.0" friction="0.0"/>
  </joint>
  <link name="jaco_upper_arm_link">
    <visual>
      <geometry>
        <mesh filename="package://jaco2_description/meshes/jaco/visual/upper_arm.dae"/>
      </geometry>
    </visual>
    <collision>
      <geometry>
        <mesh filename="package://jaco2_description/meshes/jaco/collision/upper_arm.stl"/>
      </geometry>
    </collision>
    <inertial>
      <mass value="0.968862"/>
      <origin xyz="0 0 0"/>
      <inertia ixx="0.000789" ixy="0.000008" ixz="-0.002914" iyx="0.000008" iyy="0.069034" iyz="-0.000001" izx="-0.002914" izy="-0.000001" izz="0.069005"/>
    </inertial>
  </link>
  <joint name="jaco_elbow_joint" type="revolute">
    <parent link="jaco_upper_arm_link"/>
    <child link="jaco_forearm_link"/>
    <origin rpy="0.0 0.0 3.14159265" xyz="0.410 0.0 0.00975"/>
    <axis xyz="0 0 -1"/>
    <limit effort="18.0" lower="0.331613" upper="5.95157" velocity="0.75"/>
    <dynamics damping="0.0" friction="0.0"/>
  </joint>
  <link name="jaco_forearm_link">
    <visual>
      <geometry>
        <mesh filename="package://jaco2_description/meshes/jaco/visual/forearm.dae"/>
      </geometry>
    </visual>
    <collision>
      <geometry>
        <mesh filename="package://jaco2_description/meshes/jaco/collision/forearm.stl"/>
      </geometry>
    </collision>
    <inertial>
      <mass value="0.70996"/>
      <origin xyz="0 0 0"/>
      <inertia ixx="0.000341" ixy="0.000003" ixz="-0.000034" iyx="0.000003" iyy="0.008491" iyz="-0.000000" izx="-0.000034" izy="0.000000" izz="0.008612"/>
    </inertial>
  </link>
  <joint name="jaco_wrist_1_joint" type="continuous">
    <parent link="jaco_forearm_link"/>
    <child link="jaco_wrist_1_link"/>
    <origin rpy="3.14159265 1.570796325 3.14159265" xyz="0.20725 0.0 0.0"/>
    <axis xyz="0 0 -1"/>
    <limit effort="6.8" velocity="1.571"/>
    <dynamics damping="0.0" friction="0.0"/>
  </joint>
  <link name="jaco_wrist_1_link">
    <visual>
      <geometry>
        <mesh filename="package://jaco2_description/meshes/jaco/visual/wrist_1.dae"/>
      </geometry>
    </visual>
    <collision>
      <geometry>
        <mesh filename="package://jaco2_description/meshes/jaco/collision/wrist_1.stl"/>
      </geometry>
    </collision>
    <inertial>
      <mass value="0.441232"/>
      <origin xyz="0 0 0"/>
      <inertia ixx="0.000924" ixy="0.000000" ixz="-0.000294" iyx="0.000000" iyy="0.001034" iyz="0.000000" izx="-0.000294" izy="0.000000" izz="0.000312"/>
    </inertial>
  </link>
  <joint name="jaco_wrist_2_joint" type="continuous">
    <parent link="jaco_wrist_1_link"/>
    <child link="jaco_wrist_2_link"/>
    <origin rpy="0.0 1.04719755 0.0" xyz="0.0 0.0 0.04275704155"/>
    <axis xyz="0 0 -1"/>
    <limit effort="6.8" velocity="1.571"/>
    <dynamics damping="0.0" friction="0.0"/>
  </joint>
  <link name="jaco_wrist_2_link">
    <visual>
      <geometry>
        <mesh filename="package://jaco2_description/meshes/jaco/visual/wrist_2.dae"/>
      </geometry>
    </visual>
    <collision>
      <geometry>
        <mesh filename="package://jaco2_description/meshes/jaco/collision/wrist_2.stl"/>
      </geometry>
    </collision>
    <inertial>
      <mass value="0.441232"/>
      <origin xyz="0 0 0"/>
      <inertia ixx="0.003063" ixy="0.000000" ixz="-0.000522" iyx="0.000000" iyy="0.003174" iyz="-0.000001" izx="-0.000522" izy="-0.000001" izz="0.000312"/>
    </inertial>
  </link>
  <joint name="jaco_wrist_3_joint" type="continuous">
    <parent link="jaco_wrist_2_link"/>
    <child link="jaco_wrist_3_link"/>
    <origin rpy="0.0 -1.04719755 0.0" xyz="0.0 0.0 0.08551408311"/>
    <!-- 0.08551408311-->
    <axis xyz="0 0 -1"/>
    <limit effort="6.8" velocity="1.571"/>
    <dynamics damping="0.0" friction="0.0"/>
  </joint>
  <link name="jaco_wrist_3_link">
    <visual>
      <geometry>
        <mesh filename="package://jaco2_description/meshes/jaco/visual/wrist_3.dae"/>
      </geometry>
    </visual>
    <collision>
      <geometry>
        <mesh filename="package://jaco2_description/meshes/jaco/collision/wrist_3.stl"/>
      </geometry>
    </collision>
    <inertial>
      <mass value="0.36329"/>
      <origin xyz="0 0 0"/>
      <inertia ixx="0.001908" ixy="0.000000" ixz="0.000000" iyx="0.000000" iyy="0.001907" iyz="0.000000" izx="0.000000" izy="0.000001" izz="0.000209"/>
    </inertial>
  </link>
  <joint name="jaco_ee_fixed_joint" type="fixed">
    <parent link="jaco_wrist_3_link"/>
    <child link="jaco_ee_link"/>
    <origin rpy="0.0 0.0 0.0 " xyz="0.0 0.0 0.09380704156"/>
    <!--0.09380704156-->
    <!--TODO Put back this value 0.14934664-->
  </joint>
  <link name="jaco_ee_link"/>
  <!-- <xacro:robotiq_85_gripper prefix="" parent="${prefix}ee_link" rotation="${-pi / 2.0} ${-pi / 2.0} 0" />

        <xacro:robotiq_85_gripper_transmission prefix="" />
        <xacro:jaco_arm_gazebo prefix="" />
        -->
  <!--
        <xacro:robotiq_85_gripper prefix="${prefix}" parent="${prefix}ee_link" rotation="${-pi / 2.0} ${-pi / 2.0} 0" />

        <xacro:robotiq_85_gripper_transmission prefix="${prefix}" />
        <xacro:jaco_arm_gazebo prefix="${prefix}" />
        -->
</robot>

