<?xml version="1.0"?>
<robot xmlns:xacro="http://www.ros.org/wiki/xacro">

<!--
  Author: Kelsey Hawkins 
  Contributers: Jimmy Da Silva, Ajit Krisshna N L, Muhammad Asif Rana 
-->

    <xacro:include filename="$(find jaco2_description)/urdf/grippers/robotiq_85_gripper.transmission.xacro" />
    <xacro:include filename="$(find jaco2_description)/urdf/jaco.gazebo.xacro" />
    <xacro:include filename="$(find jaco2_description)/urdf/grippers/robotiq_85_gripper.urdf.xacro" />

    <property name="M_PI" value="3.14159"/>

    <property name="pi" value="3.14159265" />

    <!-- Inertia parameters -->
    <property name="base_mass" value="0.752103" />
    <property name="shoulder_mass" value="0.839784" />
    <property name="upper_arm_mass" value="0.968862" />
    <property name="forearm_mass" value="0.709960" />
    <property name="wrist_1_mass" value="0.441232" />
    <property name="wrist_2_mass" value="0.441232" />
    <property name="wrist_3_mass" value="0.363290" />

    <xacro:macro name="jaco2_arm" params="prefix parent *origin">

        <joint name="${prefix}base_joint" type="fixed">
            <parent link="${parent}" />
            <child link = "${prefix}base_link" />
            <xacro:insert_block name="origin" />
        </joint>

        <link name="${prefix}base_link" >
            <visual>
                <geometry>
                <mesh filename="package://jaco2_description/meshes/jaco/visual/base.dae"/>
                </geometry>
            </visual>
            <collision>
                <geometry>
                <mesh filename="package://jaco2_description/meshes/jaco/collision/base.stl"/>
                </geometry>
            </collision>
            <inertial>
                <mass value="${base_mass}" />
                <origin xyz="0 0 0" />
                <inertia  ixx="0.009025"  ixy="-0.000002"  ixz="-0.000005" 
                          iyx="-0.000002"  iyy="0.009007"  iyz="0.000000" 
                          izx="-0.000005"  izy="0.000000"  izz="0.000704" />
            </inertial>
        </link>

        <joint name="${prefix}shoulder_pan_joint" type="continuous">
            <parent link="${prefix}base_link" />
            <child link = "${prefix}shoulder_link" />
            <origin xyz="0.0 0.0 0.15675" rpy="0 0 ${-pi/2.0}" /> 
            <axis xyz="0 0 -1" />
            <limit effort="18.0" velocity="0.75"/>
            <dynamics damping="0.0" friction="0.0"/>
        </joint>

        <link name="${prefix}shoulder_link">
            <visual>
                <geometry>
                    <mesh filename="package://jaco2_description/meshes/jaco/visual/shoulder.dae"/>
                </geometry>
            </visual>
            <collision>
                <geometry>
                    <mesh filename="package://jaco2_description/meshes/jaco/collision/shoulder.stl"/>
                </geometry>
            </collision>
            <inertial>
                <mass value="${shoulder_mass}" />
                <origin xyz="0 0 0" />
                <inertia  ixx="0.005735"  ixy="0.000000"  ixz="0.000000" 
                          iyx="0.000000"  iyy="0.005801"  iyz="0.000496" 
                          izx="0.000000"  izy="0.000496"  izz="0.000570" />
            </inertial>
        </link>

        <joint name="${prefix}shoulder_lift_joint" type="revolute">
            <parent link="${prefix}shoulder_link" />
            <child link = "${prefix}upper_arm_link" />
            <origin xyz="0.0 0.0 0.11875" rpy="0 ${pi / 2.0} 0" />
            <axis xyz="0 0 1" />
            <limit lower="0.872665" upper="5.41052" effort="30.5" velocity="1.0"/>
            <dynamics damping="0.0" friction="0.0"/>
        </joint>

        <link name="${prefix}upper_arm_link">
            <visual>
                <geometry>
                    <mesh filename="package://jaco2_description/meshes/jaco/visual/upper_arm.dae"/>
                </geometry>
            </visual>
            <collision>
                <geometry>
                    <mesh filename="package://jaco2_description/meshes/jaco/collision/upper_arm.stl"/>
                </geometry>
            </collision>
            <inertial>
                <mass value="${upper_arm_mass}" />
                <origin xyz="0 0 0" />
                <inertia  ixx="0.000789"  ixy="0.000008"  ixz="-0.002914" 
                          iyx="0.000008"  iyy="0.069034"  iyz="-0.000001" 
                          izx="-0.002914"  izy="-0.000001"  izz="0.069005" />
            </inertial>
        </link>

        <joint name="${prefix}elbow_joint" type="revolute">
            <parent link="${prefix}upper_arm_link" />
            <child link = "${prefix}forearm_link" />
            <origin xyz="0.410 0.0 0.00975" rpy="0.0 0.0 ${pi}" />
            <axis xyz="0 0 -1" />
            <limit lower="0.331613" upper="5.95157" effort="18.0" velocity="0.75"/>
            <dynamics damping="0.0" friction="0.0"/>
        </joint>

        <link name="${prefix}forearm_link">
            <visual>
                <geometry>
                    <mesh filename="package://jaco2_description/meshes/jaco/visual/forearm.dae"/>
                </geometry>
            </visual>
            <collision>
                <geometry>
                    <mesh filename="package://jaco2_description/meshes/jaco/collision/forearm.stl"/>
                </geometry>
            </collision>
            <inertial>
                <mass value="${forearm_mass}" />
                <origin xyz="0 0 0" />
                <inertia  ixx="0.000341"  ixy="0.000003"  ixz="-0.000034" 
                          iyx="0.000003"  iyy="0.008491"  iyz="-0.000000" 
                          izx="-0.000034"  izy="0.000000"  izz="0.008612" />
            </inertial>
        </link>

        <joint name="${prefix}wrist_1_joint" type="continuous">
            <parent link="${prefix}forearm_link" />
            <child link = "${prefix}wrist_1_link" />
            <origin xyz="0.20725 0.0 0.0" rpy="${pi} ${pi / 2.0} ${pi}" />
            <axis xyz="0 0 -1" />
            <limit effort="6.8" velocity="1.571"/>
            <dynamics damping="0.0" friction="0.0"/>
        </joint>

        <link name="${prefix}wrist_1_link">
            <visual>
                <geometry>
                    <mesh filename="package://jaco2_description/meshes/jaco/visual/wrist_1.dae"/>
                </geometry>
            </visual>
            <collision>
                <geometry>
                    <mesh filename="package://jaco2_description/meshes/jaco/collision/wrist_1.stl"/>
                </geometry>
            </collision>
            <inertial>
                <mass value="${wrist_1_mass}" />
                <origin xyz="0 0 0" />
                <inertia  ixx="0.000924"  ixy="0.000000"  ixz="-0.000294" 
                          iyx="0.000000"  iyy="0.001034"  iyz="0.000000" 
                          izx="-0.000294"  izy="0.000000"  izz="0.000312" />
            </inertial>
        </link>

        <joint name="${prefix}wrist_2_joint" type="continuous">
            <parent link="${prefix}wrist_1_link" />
            <child link = "${prefix}wrist_2_link" />
            <origin xyz="0.0 0.0 0.04275704155" rpy="0.0 ${pi / 3.0} 0.0" />
            <axis xyz="0 0 -1" />
            <limit effort="6.8" velocity="1.571"/>
            <dynamics damping="0.0" friction="0.0"/>
        </joint>

        <link name="${prefix}wrist_2_link">
            <visual>
                <geometry>
                    <mesh filename="package://jaco2_description/meshes/jaco/visual/wrist_2.dae"/>
                </geometry>
            </visual>
            <collision>
                <geometry>
                    <mesh filename="package://jaco2_description/meshes/jaco/collision/wrist_2.stl"/>
                </geometry>
            </collision>
            <inertial>
                <mass value="${wrist_2_mass}" />
                <origin xyz="0 0 0" />
                <inertia  ixx="0.003063"  ixy="0.000000"  ixz="-0.000522" 
                          iyx="0.000000"  iyy="0.003174"  iyz="-0.000001" 
                          izx="-0.000522"  izy="-0.000001"  izz="0.000312" />
            </inertial>
        </link>

        <joint name="${prefix}wrist_3_joint" type="continuous">
            <parent link="${prefix}wrist_2_link" />
            <child link = "${prefix}wrist_3_link" />
            <origin xyz="0.0 0.0 0.08551408311" rpy="0.0 ${-pi / 3.0} 0.0" /> <!-- 0.08551408311-->
            <axis xyz="0 0 -1" />
            <limit effort="6.8" velocity="1.571"/>
            <dynamics damping="0.0" friction="0.0"/>
        </joint>
        

        <link name="${prefix}wrist_3_link">
            <visual>
                <geometry>
                    <mesh filename="package://jaco2_description/meshes/jaco/visual/wrist_3.dae"/>
                </geometry>
            </visual>
            <collision>
                <geometry>
                    <mesh filename="package://jaco2_description/meshes/jaco/collision/wrist_3.stl"/>
                </geometry>
            </collision>
            <inertial>
                <mass value="${wrist_3_mass}" />
                <origin xyz="0 0 0" />
                <inertia  ixx="0.001908"  ixy="0.000000"  ixz="0.000000" 
                          iyx="0.000000"  iyy="0.001907"  iyz="0.000000" 
                          izx="0.000000"  izy="0.000001"  izz="0.000209" />
            </inertial>
        </link>


        <joint name="${prefix}ee_fixed_joint" type="fixed">
            <parent link="${prefix}wrist_3_link" />
            <child link = "${prefix}ee_link" />
            <origin xyz="0.0 0.0 0.22" rpy="0.0 0.0 0.0 " /> <!--0.09380704156--> <!--TODO Put back this value 0.14934664-->
        </joint>
        <link name="${prefix}ee_link"/>




        <!-- <xacro:robotiq_85_gripper prefix="" parent="${prefix}ee_link" rotation="${-pi / 2.0} ${-pi / 2.0} 0" />

        <xacro:robotiq_85_gripper_transmission prefix="" />
        <xacro:jaco_arm_gazebo prefix="" />
        -->
        <!--
        <xacro:robotiq_85_gripper prefix="${prefix}" parent="${prefix}ee_link" rotation="${-pi / 2.0} ${-pi / 2.0} 0" />

        <xacro:robotiq_85_gripper_transmission prefix="${prefix}" />
        <xacro:jaco_arm_gazebo prefix="${prefix}" />
        -->


  </xacro:macro>
</robot>
